Workbook

Sheet unit
A1: parameter | B1: candidate_units | C1: unit_investment_cost | D1: candidate_units (MGA) | E1: unit_investment_cost (MGA) | F1: alternative
A2: unit
A3: Electric Heater (MFH 80kW)_Anglikon_B-LVL_MFH | B3: 44 | C3: 15.2 | D3: 1 | E3: =B3*C3 -> 668.8 | F3: MGA-invest
A4: Electric Heater (MFH 80kW)_Oberdorf_B-LVL_MFH | B4: 71 | C4: 15.2 | D4: 1 | E4: =B4*C4 -> 1079.2 | F4: MGA-invest
A5: Electric Heater (MFH 80kW)_Town_B-LVL_MFH | B5: 537 | C5: 15.2 | D5: 1 | E5: =B5*C5 -> 8162.4 | F5: MGA-invest
A6: Electric Heater (SFH 17kW)_Anglikon_B-LVL_SFH | B6: 279 | C6: 10.88 | D6: 1 | E6: =B6*C6 -> 3035.52 | F6: MGA-invest
A7: Electric Heater (SFH 17kW)_Oberdorf_B-LVL_SFH | B7: 530 | C7: 10.88 | D7: 1 | E7: =B7*C7 -> 5766.4 | F7: MGA-invest
A8: Electric Heater (SFH 17kW)_Town_B-LVL_SFH | B8: 1714 | C8: 10.88 | D8: 1 | E8: =B8*C8 -> 18648.32 | F8: MGA-invest
A9: Gas Heater (MFH 80kW)_Anglikon_B-LVL_MFH | B9: 44 | C9: 80 | D9: 1 | E9: =B9*C9 -> 3520 | F9: MGA-invest
A10: Gas Heater (MFH 80kW)_Oberdorf_B-LVL_MFH | B10: 71 | C10: 80 | D10: 1 | E10: =B10*C10 -> 5680 | F10: MGA-invest
A11: Gas Heater (MFH 80kW)_Town_B-LVL_MFH | B11: 537 | C11: 80 | D11: 1 | E11: =B11*C11 -> 42960 | F11: MGA-invest
A12: Gas Heater (SFH 17kW)_Anglikon_B-LVL_SFH | B12: 279 | C12: 80 | D12: 1 | E12: =B12*C12 -> 22320 | F12: MGA-invest
A13: Gas Heater (SFH 17kW)_Oberdorf_B-LVL_SFH | B13: 530 | C13: 80 | D13: 1 | E13: =B13*C13 -> 42400 | F13: MGA-invest
A14: Gas Heater (SFH 17kW)_Town_B-LVL_SFH | B14: 1714 | C14: 80 | D14: 1 | E14: =B14*C14 -> 137120 | F14: MGA-invest
... A120: Wood Pellet CHP (25 MW)_D-LVL_Town | B120: 4 | C120: 71205 | D120: 1 | E120: =B120*C120 -> 284820 | F120: MGA-invest
A122: These technologies are ignored for MGA
A123: Heat Pump (ground MFH 80kW)_Anglikon_B-LVL_MFH
A124: Heat Pump (ground MFH 80kW)_Oberdorf_B-LVL_MFH
A125: Heat Pump (ground MFH 80kW)_Town_B-LVL_MFH
A126: Heat Pump (ground SFH 17kW)_Anglikon_B-LVL_SFH
A127: Heat Pump (ground SFH 17kW)_Oberdorf_B-LVL_SFH
A128: Heat Pump (ground SFH 17kW)_Town_B-LVL_SFH

Sheet unit_from_node
B1: parameter | C1: unit_capacity | D1: candidate_units | E1: unit_capacity (MGA)
A2: unit | B2: node
A3: CO2_emission | B3: CO2_M-LVL
A4: ElecExport_Town | B4: Electricity_D-LVL_Town | C4: 16
A5: Electric Heater (MFH 80kW)_Anglikon_B-LVL_MFH | B5: Electricity_Anglikon_B-LVL_MFH | D5: =IF(C5="","",VLOOKUP(A5,unit!$A$3:$B$120,2,FALSE)) | E5: =IF(C5<>"",C5*D5,"")
A6: Electric Heater (MFH 80kW)_Oberdorf_B-LVL_MFH | B6: Electricity_Oberdorf_B-LVL_MFH | D6: =IF(C6="","",VLOOKUP(A6,unit!$A$3:$B$120,2,FALSE)) | E6: =IF(C6<>"",C6*D6,"")
A7: Electric Heater (MFH 80kW)_Town_B-LVL_MFH | B7: Electricity_Town_B-LVL_MFH | D7: =IF(C7="","",VLOOKUP(A7,unit!$A$3:$B$120,2,FALSE)) | E7: =IF(C7<>"",C7*D7,"")
A8: Electric Heater (SFH 17kW)_Anglikon_B-LVL_SFH | B8: Electricity_Anglikon_B-LVL_SFH | D8: =IF(C8="","",VLOOKUP(A8,unit!$A$3:$B$120,2,FALSE)) | E8: =IF(C8<>"",C8*D8,"")
A9: Electric Heater (SFH 17kW)_Oberdorf_B-LVL_SFH | B9: Electricity_Oberdorf_B-LVL_SFH | D9: =IF(C9="","",VLOOKUP(A9,unit!$A$3:$B$120,2,FALSE)) | E9: =IF(C9<>"",C9*D9,"")
A10: Electric Heater (SFH 17kW)_Town_B-LVL_SFH | B10: Electricity_Town_B-LVL_SFH | D10: =IF(C10="","",VLOOKUP(A10,unit!$A$3:$B$120,2,FALSE)) | E10: =IF(C10<>"",C10*D10,"")
A11: Gas Heater (MFH 80kW)_Anglikon_B-LVL_MFH | B11: Gas_Anglikon_B-LVL_MFH | D11: =IF(C11="","",VLOOKUP(A11,unit!$A$3:$B$120,2,FALSE)) | E11: =IF(C11<>"",C11*D11,"")
A12: Gas Heater (MFH 80kW)_Oberdorf_B-LVL_MFH | B12: Gas_Oberdorf_B-LVL_MFH | D12: =IF(C12="","",VLOOKUP(A12,unit!$A$3:$B$120,2,FALSE)) | E12: =IF(C12<>"",C12*D12,"")
A13: Gas Heater (MFH 80kW)_Town_B-LVL_MFH | B13: Gas_Town_B-LVL_MFH | D13: =IF(C13="","",VLOOKUP(A13,unit!$A$3:$B$120,2,FALSE)) | E13: =IF(C13<>"",C13*D13,"")
A14: Gas Heater (SFH 17kW)_Anglikon_B-LVL_SFH | B14: Gas_Anglikon_B-LVL_SFH | D14: =IF(C14="","",VLOOKUP(A14,unit!$A$3:$B$120,2,FALSE)) | E14: =IF(C14<>"",C14*D14,"")
A15: Gas Heater (SFH 17kW)_Oberdorf_B-LVL_SFH | B15: Gas_Oberdorf_B-LVL_SFH | D15: =IF(C15="","",VLOOKUP(A15,unit!$A$3:$B$120,2,FALSE)) | E15: =IF(C15<>"",C15*D15,"")
A16: Gas Heater (SFH 17kW)_Town_B-LVL_SFH | B16: Gas_Town_B-LVL_SFH | D16: =IF(C16="","",VLOOKUP(A16,unit!$A$3:$B$120,2,FALSE)) | E16: =IF(C16<>"",C16*D16,"")
... A20: H2 Cavern 150GWh_D-LVL_Anglikon | B20: H2 Cavern 150GWh_D-LVL_Anglikon | D20: =IF(C20="","",VLOOKUP(A20,unit!$A$3:$B$120,2,FALSE)) | E20: =IF(C20<>"",C20*D20,"")
A21: H2 Cavern 150GWh_D-LVL_Anglikon | B21: Hydrogen_D-LVL_Anglikon | C21: 150 | D21: =IF(C21="","",VLOOKUP(A21,unit!$A$3:$B$120,2,FALSE)) -> 1 | E21: =IF(C21<>"",C21*D21,"") -> 150
A22: H2 Cavern 150GWh_D-LVL_Oberdorf | B22: H2 Cavern 150GWh_D-LVL_Oberdorf | D22: =IF(C22="","",VLOOKUP(A22,unit!$A$3:$B$120,2,FALSE)) | E22: =IF(C22<>"",C22*D22,"")
A23: H2 Cavern 150GWh_D-LVL_Oberdorf | B23: Hydrogen_D-LVL_Oberdorf | C23: 150 | D23: =IF(C23="","",VLOOKUP(A23,unit!$A$3:$B$120,2,FALSE)) -> 1 | E23: =IF(C23<>"",C23*D23,"") -> 150
A24: H2 Cavern 150GWh_D-LVL_Town | B24: H2 Cavern 150GWh_D-LVL_Town | D24: =IF(C24="","",VLOOKUP(A24,unit!$A$3:$B$120,2,FALSE)) | E24: =IF(C24<>"",C24*D24,"")
A25: H2 Cavern 150GWh_D-LVL_Town | B25: Hydrogen_D-LVL_Town | C25: 150 | D25: =IF(C25="","",VLOOKUP(A25,unit!$A$3:$B$120,2,FALSE)) -> 1 | E25: =IF(C25<>"",C25*D25,"") -> 150
A26: H2 Heater (MFH 80kW)_Anglikon_B-LVL_MFH | B26: Hydrogen_Anglikon_B-LVL_MFH | C26: 0.08 | D26: =IF(C26="","",VLOOKUP(A26,unit!$A$3:$B$120,2,FALSE)) -> 44 | E26: =IF(C26<>"",C26*D26,"") -> 3.52
A27: H2 Heater (MFH 80kW)_Oberdorf_B-LVL_MFH | B27: Hydrogen_Oberdorf_B-LVL_MFH | C27: 0.08 | D27: =IF(C27="","",VLOOKUP(A27,unit!$A$3:$B$120,2,FALSE)) -> 71 | E27: =IF(C27<>"",C27*D27,"") -> 5.68
A28: H2 Heater (MFH 80kW)_Town_B-LVL_MFH | B28: Hydrogen_Town_B-LVL_MFH | C28: 0.08 | D28: =IF(C28="","",VLOOKUP(A28,unit!$A$3:$B$120,2,FALSE)) -> 537 | E28: =IF(C28<>"",C28*D28,"") -> 42.96
A29: H2 Heater (SFH 17kW)_Anglikon_B-LVL_SFH | B29: Hydrogen_Anglikon_B-LVL_SFH | C29: 0.017 | D29: =IF(C29="","",VLOOKUP(A29,unit!$A$3:$B$120,2,FALSE)) -> 279 | E29: =IF(C29<>"",C29*D29,"") -> 4.743
A30: H2 Heater (SFH 17kW)_Oberdorf_B-LVL_SFH | B30: Hydrogen_Oberdorf_B-LVL_SFH | C30: 0.017 | D30: =IF(C30="","",VLOOKUP(A30,unit!$A$3:$B$120,2,FALSE)) -> 530 | E30: =IF(C30<>"",C30*D30,"") -> 9.01
A31: H2 Heater (SFH 17kW)_Town_B-LVL_SFH | B31: Hydrogen_Town_B-LVL_SFH | C31: 0.017 | D31: =IF(C31="","",VLOOKUP(A31,unit!$A$3:$B$120,2,FALSE)) -> 1714 | E31: =IF(C31<>"",C31*D31,"") -> 29.138
A32: H2 LOHC 7MWh_Anglikon_B-LVL_MFH | B32: H2 LOHC 7MWh_Anglikon_B-LVL_MFH | D32: =IF(C32="","",VLOOKUP(A32,unit!$A$3:$B$120,2,FALSE)) | E32: =IF(C32<>"",C32*D32,"")
A33: H2 LOHC 7MWh_Anglikon_B-LVL_MFH | B33: Hydrogen_Anglikon_B-LVL_MFH | C33: 70 | D33: =IF(C33="","",VLOOKUP(A33,unit!$A$3:$B$120,2,FALSE)) -> 44 | E33: =IF(C33<>"",C33*D33,"") -> 3080
A34: H2 LOHC 7MWh_Anglikon_B-LVL_SFH | B34: H2 LOHC 7MWh_Anglikon_B-LVL_SFH | D34: =IF(C34="","",VLOOKUP(A34,unit!$A$3:$B$120,2,FALSE)) | E34: =IF(C34<>"",C34*D34,"")
A35: H2 LOHC 7MWh_Anglikon_B-LVL_SFH | B35: Hydrogen_Anglikon_B-LVL_SFH | C35: 70 | D35: =IF(C35="","",VLOOKUP(A35,unit!$A$3:$B$120,2,FALSE)) -> 279 | E35: =IF(C35<>"",C35*D35,"") -> 19530
A36: H2 LOHC 7MWh_Oberdorf_B-LVL_MFH | B36: H2 LOHC 7MWh_Oberdorf_B-LVL_MFH | D36: =IF(C36="","",VLOOKUP(A36,unit!$A$3:$B$120,2,FALSE)) | E36: =IF(C36<>"",C36*D36,"")
A37: H2 LOHC 7MWh_Oberdorf_B-LVL_MFH | B37: Hydrogen_Oberdorf_B-LVL_MFH | C37: 70 | D37: =IF(C37="","",VLOOKUP(A37,unit!$A$3:$B$120,2,FALSE)) -> 71 | E37: =IF(C37<>"",C37*D37,"") -> 4970
A38: H2 LOHC 7MWh_Oberdorf_B-LVL_SFH | B38: H2 LOHC 7MWh_Oberdorf_B-LVL_SFH | D38: =IF(C38="","",VLOOKUP(A38,unit!$A$3:$B$120,2,FALSE)) | E38: =IF(C38<>"",C38*D38,"")
A39: H2 LOHC 7MWh_Oberdorf_B-LVL_SFH | B39: Hydrogen_Oberdorf_B-LVL_SFH | C39: 70 | D39: =IF(C39="","",VLOOKUP(A39,unit!$A$3:$B$120,2,FALSE)) -> 530 | E39: =IF(C39<>"",C39*D39,"") -> 37100
A40: H2 LOHC 7MWh_Town_B-LVL_MFH | B40: H2 LOHC 7MWh_Town_B-LVL_MFH | D40: =IF(C40="","",VLOOKUP(A40,unit!$A$3:$B$120,2,FALSE)) | E40: =IF(C40<>"",C40*D40,"")
A41: H2 LOHC 7MWh_Town_B-LVL_MFH | B41: Hydrogen_Town_B-LVL_MFH | C41: 70 | D41: =IF(C41="","",VLOOKUP(A41,unit!$A$3:$B$120,2,FALSE)) -> 537 | E41: =IF(C41<>"",C41*D41,"") -> 37590
A42: H2 LOHC 7MWh_Town_B-LVL_SFH | B42: H2 LOHC 7MWh_Town_B-LVL_SFH | D42: =IF(C42="","",VLOOKUP(A42,unit!$A$3:$B$120,2,FALSE)) | E42: =IF(C42<>"",C42*D42,"")
A43: H2 LOHC 7MWh_Town_B-LVL_SFH | B43: Hydrogen_Town_B-LVL_SFH | C43: 70 | D43: =IF(C43="","",VLOOKUP(A43,unit!$A$3:$B$120,2,FALSE)) -> 1714 | E43: =IF(C43<>"",C43*D43,"") -> 119980
...

Sheet unit_to_node
B1: parameter | C1: unit_capacity | D1: candidate_units | E1: unit_capacity (MGA)
A2: unit | B2: node
A3: ElecImport_Town | B3: Electricity_D-LVL_Town | C3: 16
A4: Electric Heater (MFH 80kW)_Anglikon_B-LVL_MFH | B4: Space_Heating_Anglikon_B-LVL_MFH | C4: 0.08 | D4: =IF(C4="","",VLOOKUP(A4,unit!$A$3:$B$120,2,FALSE)) -> 44 | E4: =IF(C4<>"",C4*D4,"") -> 3.52
A5: Electric Heater (MFH 80kW)_Oberdorf_B-LVL_MFH | B5: Space_Heating_Oberdorf_B-LVL_MFH | C5: 0.08 | D5: =IF(C5="","",VLOOKUP(A5,unit!$A$3:$B$120,2,FALSE)) -> 71 | E5: =IF(C5<>"",C5*D5,"") -> 5.68
A6: Electric Heater (MFH 80kW)_Town_B-LVL_MFH | B6: Space_Heating_Town_B-LVL_MFH | C6: 0.08 | D6: =IF(C6="","",VLOOKUP(A6,unit!$A$3:$B$120,2,FALSE)) -> 537 | E6: =IF(C6<>"",C6*D6,"") -> 42.96
A7: Electric Heater (SFH 17kW)_Anglikon_B-LVL_SFH | B7: Space_Heating_Anglikon_B-LVL_SFH | C7: 0.017 | D7: =IF(C7="","",VLOOKUP(A7,unit!$A$3:$B$120,2,FALSE)) -> 279 | E7: =IF(C7<>"",C7*D7,"") -> 4.743
A8: Electric Heater (SFH 17kW)_Oberdorf_B-LVL_SFH | B8: Space_Heating_Oberdorf_B-LVL_SFH | C8: 0.017 | D8: =IF(C8="","",VLOOKUP(A8,unit!$A$3:$B$120,2,FALSE)) -> 530 | E8: =IF(C8<>"",C8*D8,"") -> 9.01
A9: Electric Heater (SFH 17kW)_Town_B-LVL_SFH | B9: Space_Heating_Town_B-LVL_SFH | C9: 0.017 | D9: =IF(C9="","",VLOOKUP(A9,unit!$A$3:$B$120,2,FALSE)) -> 1714 | E9: =IF(C9<>"",C9*D9,"") -> 29.138
A10: Gas Heater (MFH 80kW)_Anglikon_B-LVL_MFH | B10: CO2_M-LVL | D10: =IF(C10="","",VLOOKUP(A10,unit!$A$3:$B$120,2,FALSE)) | E10: =IF(C10<>"",C10*D10,"")
A11: Gas Heater (MFH 80kW)_Anglikon_B-LVL_MFH | B11: Space_Heating_Anglikon_B-LVL_MFH | C11: 0.08 | D11: =IF(C11="","",VLOOKUP(A11,unit!$A$3:$B$120,2,FALSE)) -> 44 | E11: =IF(C11<>"",C11*D11,"") -> 3.52
A12: Gas Heater (MFH 80kW)_Oberdorf_B-LVL_MFH | B12: CO2_M-LVL | D12: =IF(C12="","",VLOOKUP(A12,unit!$A$3:$B$120,2,FALSE)) | E12: =IF(C12<>"",C12*D12,"")
A13: Gas Heater (MFH 80kW)_Oberdorf_B-LVL_MFH | B13: Space_Heating_Oberdorf_B-LVL_MFH | C13: 0.08 | D13: =IF(C13="","",VLOOKUP(A13,unit!$A$3:$B$120,2,FALSE)) -> 71 | E13: =IF(C13<>"",C13*D13,"") -> 5.68
A14: Gas Heater (MFH 80kW)_Town_B-LVL_MFH | B14: CO2_M-LVL | D14: =IF(C14="","",VLOOKUP(A14,unit!$A$3:$B$120,2,FALSE)) | E14: =IF(C14<>"",C14*D14,"")
A15: Gas Heater (MFH 80kW)_Town_B-LVL_MFH | B15: Space_Heating_Town_B-LVL_MFH | C15: 0.08 | D15: =IF(C15="","",VLOOKUP(A15,unit!$A$3:$B$120,2,FALSE)) -> 537 | E15: =IF(C15<>"",C15*D15,"") -> 42.96
A16: Gas Heater (SFH 17kW)_Anglikon_B-LVL_SFH | B16: CO2_M-LVL | D16: =IF(C16="","",VLOOKUP(A16,unit!$A$3:$B$120,2,FALSE)) | E16: =IF(C16<>"",C16*D16,"")
A17: Gas Heater (SFH 17kW)_Anglikon_B-LVL_SFH | B17: Space_Heating_Anglikon_B-LVL_SFH | C17: 0.017 | D17: =IF(C17="","",VLOOKUP(A17,unit!$A$3:$B$120,2,FALSE)) -> 279 | E17: =IF(C17<>"",C17*D17,"") -> 4.743
A18: Gas Heater (SFH 17kW)_Oberdorf_B-LVL_SFH | B18: CO2_M-LVL | D18: =IF(C18="","",VLOOKUP(A18,unit!$A$3:$B$120,2,FALSE)) | E18: =IF(C18<>"",C18*D18,"")
A19: Gas Heater (SFH 17kW)_Oberdorf_B-LVL_SFH | B19: Space_Heating_Oberdorf_B-LVL_SFH | C19: 0.017 | D19: =IF(C19="","",VLOOKUP(A19,unit!$A$3:$B$120,2,FALSE)) -> 530 | E19: =IF(C19<>"",C19*D19,"") -> 9.01
A20: Gas Heater (SFH 17kW)_Town_B-LVL_SFH | B20: CO2_M-LVL | D20: =IF(C20="","",VLOOKUP(A20,unit!$A$3:$B$120,2,FALSE)) | E20: =IF(C20<>"",C20*D20,"")
A21: Gas Heater (SFH 17kW)_Town_B-LVL_SFH | B21: Space_Heating_Town_B-LVL_SFH | C21: 0.017 | D21: =IF(C21="","",VLOOKUP(A21,unit!$A$3:$B$120,2,FALSE)) -> 1714 | E21: =IF(C21<>"",C21*D21,"") -> 29.138
A22: Gas Turbine (40 MW)_D-LVL_Anglikon | B22: CO2_M-LVL | D22: =IF(C22="","",VLOOKUP(A22,unit!$A$3:$B$120,2,FALSE)) | E22: =IF(C22<>"",C22*D22,"")
A23: Gas Turbine (40 MW)_D-LVL_Anglikon | B23: Electricity_D-LVL_Anglikon | C23: 40 | D23: =IF(C23="","",VLOOKUP(A23,unit!$A$3:$B$120,2,FALSE)) -> 10 | E23: =IF(C23<>"",C23*D23,"") -> 400
A24: Gas Turbine (40 MW)_D-LVL_Oberdorf | B24: CO2_M-LVL | D24: =IF(C24="","",VLOOKUP(A24,unit!$A$3:$B$120,2,FALSE)) | E24: =IF(C24<>"",C24*D24,"")
A25: Gas Turbine (40 MW)_D-LVL_Oberdorf | B25: Electricity_D-LVL_Oberdorf | C25: 40 | D25: =IF(C25="","",VLOOKUP(A25,unit!$A$3:$B$120,2,FALSE)) -> 10 | E25: =IF(C25<>"",C25*D25,"") -> 400
A26: Gas Turbine (40 MW)_D-LVL_Town | B26: CO2_M-LVL | D26: =IF(C26="","",VLOOKUP(A26,unit!$A$3:$B$120,2,FALSE)) | E26: =IF(C26<>"",C26*D26,"")
A27: Gas Turbine (40 MW)_D-LVL_Town | B27: Electricity_D-LVL_Town | C27: 40 | D27: =IF(C27="","",VLOOKUP(A27,unit!$A$3:$B$120,2,FALSE)) -> 10 | E27: =IF(C27<>"",C27*D27,"") -> 400
A28: H2 Cavern 150GWh_D-LVL_Anglikon | B28: H2 Cavern 150GWh_D-LVL_Anglikon | D28: =IF(C28="","",VLOOKUP(A28,unit!$A$3:$B$120,2,FALSE)) | E28: =IF(C28<>"",C28*D28,"")
A29: H2 Cavern 150GWh_D-LVL_Anglikon | B29: Hydrogen_D-LVL_Anglikon | C29: 150 | D29: =IF(C29="","",VLOOKUP(A29,unit!$A$3:$B$120,2,FALSE)) -> 1 | E29: =IF(C29<>"",C29*D29,"") -> 150
A30: H2 Cavern 150GWh_D-LVL_Oberdorf | B30: H2 Cavern 150GWh_D-LVL_Oberdorf | D30: =IF(C30="","",VLOOKUP(A30,unit!$A$3:$B$120,2,FALSE)) | E30: =IF(C30<>"",C30*D30,"")
A31: H2 Cavern 150GWh_D-LVL_Oberdorf | B31: Hydrogen_D-LVL_Oberdorf | C31: 150 | D31: =IF(C31="","",VLOOKUP(A31,unit!$A$3:$B$120,2,FALSE)) -> 1 | E31: =IF(C31<>"",C31*D31,"") -> 150
A32: H2 Cavern 150GWh_D-LVL_Town | B32: H2 Cavern 150GWh_D-LVL_Town | D32: =IF(C32="","",VLOOKUP(A32,unit!$A$3:$B$120,2,FALSE)) | E32: =IF(C32<>"",C32*D32,"")
A33: H2 Cavern 150GWh_D-LVL_Town | B33: Hydrogen_D-LVL_Town | C33: 150 | D33: =IF(C33="","",VLOOKUP(A33,unit!$A$3:$B$120,2,FALSE)) -> 1 | E33: =IF(C33<>"",C33*D33,"") -> 150
A34: H2 Heater (MFH 80kW)_Anglikon_B-LVL_MFH | B34: Space_Heating_Anglikon_B-LVL_MFH | D34: =IF(C34="","",VLOOKUP(A34,unit!$A$3:$B$120,2,FALSE)) | E34: =IF(C34<>"",C34*D34,"")
A35: H2 Heater (MFH 80kW)_Oberdorf_B-LVL_MFH | B35: Space_Heating_Oberdorf_B-LVL_MFH | D35: =IF(C35="","",VLOOKUP(A35,unit!$A$3:$B$120,2,FALSE)) | E35: =IF(C35<>"",C35*D35,"")
A36: H2 Heater (MFH 80kW)_Town_B-LVL_MFH | B36: Space_Heating_Town_B-LVL_MFH | D36: =IF(C36="","",VLOOKUP(A36,unit!$A$3:$B$120,2,FALSE)) | E36: =IF(C36<>"",C36*D36,"")
A37: H2 Heater (SFH 17kW)_Anglikon_B-LVL_SFH | B37: Space_Heating_Anglikon_B-LVL_SFH | D37: =IF(C37="","",VLOOKUP(A37,unit!$A$3:$B$120,2,FALSE)) | E37: =IF(C37<>"",C37*D37,"")
A38: H2 Heater (SFH 17kW)_Oberdorf_B-LVL_SFH | B38: Space_Heating_Oberdorf_B-LVL_SFH | D38: =IF(C38="","",VLOOKUP(A38,unit!$A$3:$B$120,2,FALSE)) | E38: =IF(C38<>"",C38*D38,"")
A39: H2 Heater (SFH 17kW)_Town_B-LVL_SFH | B39: Space_Heating_Town_B-LVL_SFH | D39: =IF(C39="","",VLOOKUP(A39,unit!$A$3:$B$120,2,FALSE)) | E39: =IF(C39<>"",C39*D39,"")
A40: H2 LOHC 7MWh_Anglikon_B-LVL_MFH | B40: H2 LOHC 7MWh_Anglikon_B-LVL_MFH | D40: =IF(C40="","",VLOOKUP(A40,unit!$A$3:$B$120,2,FALSE)) | E40: =IF(C40<>"",C40*D40,"")
...

Sheet node
A1: parameter | B1: candidate_storages | C1: node_state_cap | D1: candidate_storages (MGA) | E1: node_state_cap (MGA) | F1: alternative
A2: node
A3: H2 Cavern 150GWh_D-LVL_Anglikon | B3: 1 | C3: 150000 | D3: 1 | E3: =B3*C3 -> 150000 | F3: MGA-invest
A4: H2 Cavern 150GWh_D-LVL_Oberdorf | B4: 1 | C4: 150000 | D4: 1 | E4: =B4*C4 -> 150000 | F4: MGA-invest
A5: H2 Cavern 150GWh_D-LVL_Town | B5: 1 | C5: 150000 | D5: 1 | E5: =B5*C5 -> 150000 | F5: MGA-invest
A6: H2 LOHC 7MWh_Anglikon_B-LVL_MFH | B6: 44 | C6: 7 | D6: 1 | E6: =B6*C6 -> 308 | F6: MGA-invest
A7: H2 LOHC 7MWh_Anglikon_B-LVL_SFH | B7: 279 | C7: 7 | D7: 1 | E7: =B7*C7 -> 1953 | F7: MGA-invest
A8: H2 LOHC 7MWh_Oberdorf_B-LVL_MFH | B8: 71 | C8: 7 | D8: 1 | E8: =B8*C8 -> 497 | F8: MGA-invest
A9: H2 LOHC 7MWh_Oberdorf_B-LVL_SFH | B9: 530 | C9: 7 | D9: 1 | E9: =B9*C9 -> 3710 | F9: MGA-invest
A10: H2 LOHC 7MWh_Town_B-LVL_MFH | B10: 537 | C10: 7 | D10: 1 | E10: =B10*C10 -> 3759 | F10: MGA-invest
A11: H2 LOHC 7MWh_Town_B-LVL_SFH | B11: 1714 | C11: 7 | D11: 1 | E11: =B11*C11 -> 11998 | F11: MGA-invest
A12: H2 Tank 16.7MWh_D-LVL_Anglikon | B12: 60 | C12: 16.7 | D12: 1 | E12: =B12*C12 -> 1002 | F12: MGA-invest
A13: H2 Tank 16.7MWh_D-LVL_Oberdorf | B13: 60 | C13: 16.7 | D13: 1 | E13: =B13*C13 -> 1002 | F13: MGA-invest
A14: H2 Tank 16.7MWh_D-LVL_Town | B14: 60 | C14: 16.7 | D14: 1 | E14: =B14*C14 -> 1002 | F14: MGA-invest
... A41: Vanadium Redox Flow Battery 2MWh_Town_B-LVL_SFH | B41: 1714 | C41: 0.65 | D41: 1 | E41: =B41*C41 -> 1114.1 | F41: MGA-invest
